Internal Server Error: /admin/store/product/add/
Traceback (most recent call last):
  File "C:\Users\user\Shop\venv\Lib\site-packages\django\core\handlers\exception.py", line 55, in inner
    response = get_response(request)
               ^^^^^^^^^^^^^^^^^^^^^
  File "C:\Users\user\Shop\venv\Lib\site-packages\django\core\handlers\base.py", line 197, in _get_response
    response = wrapped_callback(request, *callback_args, **callback_kwargs)
               ^^^^^^^^^^^^^^^^^^^^^^^^^^^^^^^^^^^^^^^^^^^^^^^^^^^^^^^^^^^^
  File "C:\Users\user\Shop\venv\Lib\site-packages\django\contrib\admin\options.py", line 716, in wrapper
    return self.admin_site.admin_view(view)(*args, **kwargs)
           ^^^^^^^^^^^^^^^^^^^^^^^^^^^^^^^^^^^^^^^^^^^^^^^^^
  File "C:\Users\user\Shop\venv\Lib\site-packages\django\utils\decorators.py", line 188, in _view_wrapper
    result = _process_exception(request, e)
             ^^^^^^^^^^^^^^^^^^^^^^^^^^^^^^
  File "C:\Users\user\Shop\venv\Lib\site-packages\django\utils\decorators.py", line 186, in _view_wrapper
    response = view_func(request, *args, **kwargs)
               ^^^^^^^^^^^^^^^^^^^^^^^^^^^^^^^^^^^
  File "C:\Users\user\Shop\venv\Lib\site-packages\django\views\decorators\cache.py", line 80, in _view_wrapper
    response = view_func(request, *args, **kwargs)
               ^^^^^^^^^^^^^^^^^^^^^^^^^^^^^^^^^^^
  File "C:\Users\user\Shop\venv\Lib\site-packages\django\contrib\admin\sites.py", line 240, in inner
    return view(request, *args, **kwargs)
           ^^^^^^^^^^^^^^^^^^^^^^^^^^^^^^
  File "C:\Users\user\Shop\venv\Lib\site-packages\django\contrib\admin\options.py", line 1945, in add_view
    return self.changeform_view(request, None, form_url, extra_context)
           ^^^^^^^^^^^^^^^^^^^^^^^^^^^^^^^^^^^^^^^^^^^^^^^^^^^^^^^^^^^^
  File "C:\Users\user\Shop\venv\Lib\site-packages\django\utils\decorators.py", line 48, in _wrapper
    return bound_method(*args, **kwargs)
           ^^^^^^^^^^^^^^^^^^^^^^^^^^^^^
  File "C:\Users\user\Shop\venv\Lib\site-packages\django\utils\decorators.py", line 188, in _view_wrapper
    result = _process_exception(request, e)
             ^^^^^^^^^^^^^^^^^^^^^^^^^^^^^^
  File "C:\Users\user\Shop\venv\Lib\site-packages\django\utils\decorators.py", line 186, in _view_wrapper
    response = view_func(request, *args, **kwargs)
               ^^^^^^^^^^^^^^^^^^^^^^^^^^^^^^^^^^^
  File "C:\Users\user\Shop\venv\Lib\site-packages\django\contrib\admin\options.py", line 1804, in changeform_view
    return self._changeform_view(request, object_id, form_url, extra_context)
           ^^^^^^^^^^^^^^^^^^^^^^^^^^^^^^^^^^^^^^^^^^^^^^^^^^^^^^^^^^^^^^^^^^
  File "C:\Users\user\Shop\venv\Lib\site-packages\django\contrib\admin\options.py", line 1855, in _changeform_view
    self.save_model(request, new_object, form, not add)
  File "C:\Users\user\Shop\venv\Lib\site-packages\django\contrib\admin\options.py", line 1259, in save_model
    obj.save()
  File "C:\Users\user\Shop\venv\Lib\site-packages\django\db\models\base.py", line 822, in save
    self.save_base(
  File "C:\Users\user\Shop\venv\Lib\site-packages\django\db\models\base.py", line 909, in save_base
    updated = self._save_table(
              ^^^^^^^^^^^^^^^^^
  File "C:\Users\user\Shop\venv\Lib\site-packages\django\db\models\base.py", line 1071, in _save_table
    results = self._do_insert(
              ^^^^^^^^^^^^^^^^
  File "C:\Users\user\Shop\venv\Lib\site-packages\django\db\models\base.py", line 1112, in _do_insert
    return manager._insert(
           ^^^^^^^^^^^^^^^^
  File "C:\Users\user\Shop\venv\Lib\site-packages\django\db\models\manager.py", line 87, in manager_method
    return getattr(self.get_queryset(), name)(*args, **kwargs)
           ^^^^^^^^^^^^^^^^^^^^^^^^^^^^^^^^^^^^^^^^^^^^^^^^^^^
  File "C:\Users\user\Shop\venv\Lib\site-packages\django\db\models\query.py", line 1847, in _insert
    return query.get_compiler(using=using).execute_sql(returning_fields)
           ^^^^^^^^^^^^^^^^^^^^^^^^^^^^^^^^^^^^^^^^^^^^^^^^^^^^^^^^^^^^^
  File "C:\Users\user\Shop\venv\Lib\site-packages\django\db\models\sql\compiler.py", line 1822, in execute_sql
    for sql, params in self.as_sql():
                       ^^^^^^^^^^^^^
  File "C:\Users\user\Shop\venv\Lib\site-packages\django\db\models\sql\compiler.py", line 1747, in as_sql
    self.prepare_value(field, self.pre_save_val(field, obj))
                              ^^^^^^^^^^^^^^^^^^^^^^^^^^^^^
  File "C:\Users\user\Shop\venv\Lib\site-packages\django\db\models\sql\compiler.py", line 1695, in pre_save_val
    return field.pre_save(obj, add=True)
           ^^^^^^^^^^^^^^^^^^^^^^^^^^^^^
  File "C:\Users\user\Shop\venv\Lib\site-packages\cloudinary\models.py", line 112, in pre_save
    instance_value = uploader.upload_resource(value, **options)
                     ^^^^^^^^^^^^^^^^^^^^^^^^^^^^^^^^^^^^^^^^^^
  File "C:\Users\user\Shop\venv\Lib\site-packages\cloudinary\uploader.py", line 64, in upload_resource
    result = upload_func(file, **options)
             ^^^^^^^^^^^^^^^^^^^^^^^^^^^^
  File "C:\Users\user\Shop\venv\Lib\site-packages\cloudinary\uploader.py", line 45, in upload
    return call_cacheable_api("upload", params, file=file, **options)
           ^^^^^^^^^^^^^^^^^^^^^^^^^^^^^^^^^^^^^^^^^^^^^^^^^^^^^^^^^^
  File "C:\Users\user\Shop\venv\Lib\site-packages\cloudinary\uploader.py", line 462, in call_cacheable_api
    result = call_api(action, params, http_headers, return_error, unsigned, file, timeout, **options)
             ^^^^^^^^^^^^^^^^^^^^^^^^^^^^^^^^^^^^^^^^^^^^^^^^^^^^^^^^^^^^^^^^^^^^^^^^^^^^^^^^^^^^^^^^
  File "C:\Users\user\Shop\venv\Lib\site-packages\cloudinary\uploader.py", line 487, in call_api
    params = utils.sign_request(params, options)
             ^^^^^^^^^^^^^^^^^^^^^^^^^^^^^^^^^^^
  File "C:\Users\user\Shop\venv\Lib\site-packages\cloudinary\utils.py", line 617, in sign_request
    raise ValueError("Must supply api_key")
ValueError: Must supply api_key
"POST /admin/store/product/add/ HTTP/1.1" 500 205712
